schematic = {
	size = {x=6, y=7, z=5},
	yslice_prob = {
		{ypos=0, prob=254},
		{ypos=1, prob=254},
		{ypos=2, prob=254},
		{ypos=3, prob=254},
		{ypos=4, prob=254},
		{ypos=5, prob=254},
		{ypos=6, prob=254},
	},
	data = {
		{name="air", prob=0, param2=0},
		{name="air", prob=0, param2=0},
		{name="air", prob=0, param2=0},
		{name="air", prob=0, param2=0},
		{name="air", prob=0, param2=0},
		{name="air", prob=0, param2=0},
		{name="air", prob=0, param2=0},
		{name="air", prob=0, param2=0},
		{name="air", prob=0, param2=0},
		{name="air", prob=0, param2=0},
		{name="air", prob=0, param2=0},
		{name="air", prob=0, param2=0},
		{name="air", prob=0, param2=0},
		{name="air", prob=0, param2=0},
		{name="air", prob=0, param2=0},
		{name="air", prob=0, param2=0},
		{name="air", prob=0, param2=0},
		{name="air", prob=0, param2=0},
		{name="air", prob=0, param2=0},
		{name="air", prob=0, param2=0},
		{name="cherrytree:blossom_leaves", prob=254, param2=1},
		{name="cherrytree:blossom_leaves", prob=254, param2=1},
		{name="cherrytree:blossom_leaves", prob=254, param2=1},
		{name="cherrytree:blossom_leaves", prob=126, param2=1},
		{name="air", prob=0, param2=0},
		{name="air", prob=0, param2=0},
		{name="air", prob=0, param2=0},
		{name="cherrytree:blossom_leaves", prob=126, param2=1},
		{name="air", prob=0, param2=0},
		{name="air", prob=0, param2=0},
		{name="air", prob=0, param2=0},
		{name="air", prob=0, param2=0},
		{name="air", prob=0, param2=0},
		{name="air", prob=0, param2=0},
		{name="air", prob=0, param2=0},
		{name="air", prob=0, param2=0},
		{name="air", prob=0, param2=0},
		{name="air", prob=0, param2=0},
		{name="air", prob=0, param2=0},
		{name="air", prob=0, param2=0},
		{name="air", prob=0, param2=0},
		{name="air", prob=0, param2=0},
		{name="air", prob=0, param2=0},
		{name="air", prob=0, param2=0},
		{name="air", prob=0, param2=0},
		{name="air", prob=0, param2=0},
		{name="air", prob=0, param2=0},
		{name="air", prob=0, param2=0},
		{name="air", prob=0, param2=0},
		{name="air", prob=0, param2=0},
		{name="air", prob=0, param2=0},
		{name="air", prob=0, param2=0},
		{name="air", prob=0, param2=0},
		{name="air", prob=0, param2=0},
		{name="air", prob=0, param2=0},
		{name="air", prob=0, param2=0},
		{name="air", prob=0, param2=0},
		{name="air", prob=0, param2=0},
		{name="air", prob=0, param2=0},
		{name="air", prob=0, param2=0},
		{name="cherrytree:blossom_leaves", prob=254, param2=1},
		{name="cherrytree:blossom_leaves", prob=254, param2=1},
		{name="cherrytree:blossom_leaves", prob=254, param2=1},
		{name="cherrytree:blossom_leaves", prob=254, param2=1},
		{name="cherrytree:blossom_leaves", prob=254, param2=1},
		{name="cherrytree:blossom_leaves", prob=254, param2=1},
		{name="air", prob=0, param2=0},
		{name="cherrytree:blossom_leaves", prob=126, param2=1},
		{name="cherrytree:blossom_leaves", prob=254, param2=1},
		{name="cherrytree:blossom_leaves", prob=254, param2=1},
		{name="cherrytree:blossom_leaves", prob=254, param2=1},
		{name="air", prob=0, param2=0},
		{name="air", prob=0, param2=0},
		{name="air", prob=0, param2=0},
		{name="cherrytree:blossom_leaves", prob=254, param2=1},
		{name="cherrytree:blossom_leaves", prob=254, param2=1},
		{name="air", prob=0, param2=0},
		{name="air", prob=0, param2=0},
		{name="air", prob=0, param2=0},
		{name="air", prob=0, param2=0},
		{name="air", prob=0, param2=0},
		{name="cherrytree:blossom_leaves", prob=126, param2=1},
		{name="air", prob=0, param2=0},
		{name="air", prob=0, param2=0},
		{name="air", prob=0, param2=0},
		{name="air", prob=0, param2=0},
		{name="cherrytree:trunk", prob=254, param2=2},
		{name="air", prob=0, param2=0},
		{name="air", prob=0, param2=0},
		{name="air", prob=0, param2=0},
		{name="air", prob=0, param2=0},
		{name="air", prob=0, param2=0},
		{name="cherrytree:trunk", prob=254, param2=2},
		{name="air", prob=0, param2=0},
		{name="air", prob=0, param2=0},
		{name="air", prob=0, param2=0},
		{name="air", prob=0, param2=0},
		{name="air", prob=0, param2=0},
		{name="cherrytree:trunk", prob=254, param2=2},
		{name="air", prob=0, param2=0},
		{name="air", prob=0, param2=0},
		{name="air", prob=0, param2=0},
		{name="cherrytree:blossom_leaves", prob=254, param2=1},
		{name="cherrytree:blossom_leaves", prob=254, param2=1},
		{name="cherrytree:trunk", prob=254, param2=3},
		{name="cherrytree:blossom_leaves", prob=254, param2=1},
		{name="cherrytree:blossom_leaves", prob=254, param2=1},
		{name="cherrytree:blossom_leaves", prob=254, param2=1},
		{name="air", prob=0, param2=0},
		{name="cherrytree:blossom_leaves", prob=254, param2=1},
		{name="cherrytree:trunk", prob=254, param2=3},
		{name="cherrytree:trunk", prob=254, param2=3},
		{name="cherrytree:blossom_leaves", prob=254, param2=1},
		{name="air", prob=0, param2=0},
		{name="air", prob=0, param2=0},
		{name="air", prob=0, param2=0},
		{name="cherrytree:blossom_leaves", prob=254, param2=1},
		{name="cherrytree:trunk", prob=254, param2=3},
		{name="cherrytree:blossom_leaves", prob=126, param2=1},
		{name="air", prob=0, param2=0},
		{name="air", prob=0, param2=0},
		{name="air", prob=0, param2=0},
		{name="cherrytree:blossom_leaves", prob=254, param2=1},
		{name="cherrytree:blossom_leaves", prob=254, param2=1},
		{name="air", prob=0, param2=0},
		{name="air", prob=0, param2=0},
		{name="air", prob=0, param2=0},
		{name="air", prob=0, param2=0},
		{name="air", prob=0, param2=0},
		{name="air", prob=0, param2=0},
		{name="air", prob=0, param2=0},
		{name="air", prob=0, param2=0},
		{name="air", prob=0, param2=0},
		{name="air", prob=0, param2=0},
		{name="air", prob=0, param2=0},
		{name="air", prob=0, param2=0},
		{name="air", prob=0, param2=0},
		{name="air", prob=0, param2=0},
		{name="air", prob=0, param2=0},
		{name="air", prob=0, param2=0},
		{name="air", prob=0, param2=0},
		{name="air", prob=0, param2=0},
		{name="air", prob=0, param2=0},
		{name="air", prob=0, param2=0},
		{name="cherrytree:blossom_leaves", prob=254, param2=1},
		{name="cherrytree:blossom_leaves", prob=254, param2=1},
		{name="cherrytree:blossom_leaves", prob=254, param2=1},
		{name="cherrytree:blossom_leaves", prob=254, param2=1},
		{name="cherrytree:blossom_leaves", prob=254, param2=1},
		{name="cherrytree:blossom_leaves", prob=254, param2=1},
		{name="air", prob=0, param2=0},
		{name="cherrytree:blossom_leaves", prob=254, param2=1},
		{name="cherrytree:blossom_leaves", prob=254, param2=1},
		{name="cherrytree:blossom_leaves", prob=254, param2=1},
		{name="cherrytree:blossom_leaves", prob=254, param2=1},
		{name="air", prob=0, param2=0},
		{name="air", prob=0, param2=0},
		{name="air", prob=0, param2=0},
		{name="cherrytree:blossom_leaves", prob=254, param2=1},
		{name="cherrytree:blossom_leaves", prob=254, param2=1},
		{name="air", prob=0, param2=0},
		{name="air", prob=0, param2=0},
		{name="air", prob=0, param2=0},
		{name="air", prob=0, param2=0},
		{name="cherrytree:blossom_leaves", prob=254, param2=1},
		{name="air", prob=0, param2=0},
		{name="air", prob=0, param2=0},
		{name="air", prob=0, param2=0},
		{name="air", prob=0, param2=0},
		{name="air", prob=0, param2=0},
		{name="air", prob=0, param2=0},
		{name="air", prob=0, param2=0},
		{name="air", prob=0, param2=0},
		{name="air", prob=0, param2=0},
		{name="air", prob=0, param2=0},
		{name="air", prob=0, param2=0},
		{name="air", prob=0, param2=0},
		{name="air", prob=0, param2=0},
		{name="air", prob=0, param2=0},
		{name="air", prob=0, param2=0},
		{name="air", prob=0, param2=0},
		{name="air", prob=0, param2=0},
		{name="air", prob=0, param2=0},
		{name="air", prob=0, param2=0},
		{name="air", prob=0, param2=0},
		{name="air", prob=0, param2=0},
		{name="cherrytree:blossom_leaves", prob=126, param2=1},
		{name="cherrytree:blossom_leaves", prob=254, param2=1},
		{name="cherrytree:blossom_leaves", prob=254, param2=1},
		{name="air", prob=0, param2=0},
		{name="air", prob=0, param2=0},
		{name="air", prob=0, param2=0},
		{name="air", prob=0, param2=0},
		{name="air", prob=0, param2=0},
		{name="air", prob=0, param2=0},
		{name="air", prob=0, param2=0},
		{name="air", prob=0, param2=0},
		{name="air", prob=0, param2=0},
		{name="air", prob=0, param2=0},
		{name="air", prob=0, param2=0},
		{name="air", prob=0, param2=0},
		{name="air", prob=0, param2=0},
		{name="air", prob=0, param2=0},
		{name="air", prob=0, param2=0},
		{name="air", prob=0, param2=0},
		{name="air", prob=0, param2=0},
		{name="air", prob=0, param2=0},
		{name="air", prob=0, param2=0},
		{name="air", prob=0, param2=0},
		{name="air", prob=0, param2=0},
	},
}
