schematic = {
	size = {x=3, y=6, z=3},
	yslice_prob = {
		{ypos=0, prob=254},
		{ypos=1, prob=254},
		{ypos=2, prob=254},
		{ypos=3, prob=254},
		{ypos=4, prob=254},
		{ypos=5, prob=254},
	},
	data = {
		{name="air", prob=0, param2=0},
		{name="air", prob=0, param2=0},
		{name="air", prob=0, param2=0},
		{name="air", prob=0, param2=0},
		{name="air", prob=0, param2=0},
		{name="air", prob=0, param2=0},
		{name="air", prob=0, param2=0},
		{name="air", prob=0, param2=0},
		{name="air", prob=0, param2=0},
		{name="pomegranate:leaves", prob=254, param2=1},
		{name="pomegranate:pomegranate", prob=126, param2=1},
		{name="pomegranate:leaves", prob=254, param2=1},
		{name="pomegranate:leaves", prob=254, param2=1},
		{name="pomegranate:leaves", prob=254, param2=1},
		{name="pomegranate:leaves", prob=254, param2=1},
		{name="air", prob=0, param2=0},
		{name="air", prob=0, param2=0},
		{name="air", prob=0, param2=0},
		{name="air", prob=0, param2=0},
		{name="pomegranate:trunk", prob=254, param2=1},
		{name="air", prob=0, param2=0},
		{name="air", prob=0, param2=0},
		{name="pomegranate:trunk", prob=254, param2=1},
		{name="air", prob=0, param2=0},
		{name="air", prob=0, param2=0},
		{name="pomegranate:trunk", prob=254, param2=1},
		{name="air", prob=0, param2=0},
		{name="pomegranate:pomegranate", prob=126, param2=1},
		{name="pomegranate:leaves", prob=254, param2=1},
		{name="pomegranate:pomegranate", prob=126, param2=1},
		{name="pomegranate:leaves", prob=254, param2=1},
		{name="pomegranate:leaves", prob=254, param2=1},
		{name="pomegranate:leaves", prob=254, param2=1},
		{name="air", prob=0, param2=0},
		{name="pomegranate:leaves", prob=126, param2=1},
		{name="air", prob=0, param2=0},
		{name="air", prob=0, param2=0},
		{name="air", prob=0, param2=0},
		{name="air", prob=0, param2=0},
		{name="air", prob=0, param2=0},
		{name="air", prob=0, param2=0},
		{name="air", prob=0, param2=0},
		{name="air", prob=0, param2=0},
		{name="air", prob=0, param2=0},
		{name="air", prob=0, param2=0},
		{name="pomegranate:leaves", prob=254, param2=1},
		{name="pomegranate:pomegranate", prob=254, param2=1},
		{name="pomegranate:leaves", prob=254, param2=1},
		{name="pomegranate:leaves", prob=254, param2=1},
		{name="pomegranate:leaves", prob=254, param2=1},
		{name="pomegranate:leaves", prob=254, param2=1},
		{name="air", prob=0, param2=0},
		{name="air", prob=0, param2=0},
		{name="air", prob=0, param2=0},
	},
}
