schematic = {
	size = {x=5, y=7, z=5},
	yslice_prob = {
		{ypos=0, prob=254},
		{ypos=1, prob=254},
		{ypos=2, prob=254},
		{ypos=3, prob=254},
		{ypos=4, prob=254},
		{ypos=5, prob=254},
		{ypos=6, prob=254},
	},
	data = {
		{name="air", prob=0, param2=0},
		{name="air", prob=0, param2=0},
		{name="air", prob=0, param2=0},
		{name="air", prob=0, param2=0},
		{name="air", prob=0, param2=0},
		{name="air", prob=0, param2=0},
		{name="air", prob=0, param2=0},
		{name="air", prob=0, param2=0},
		{name="air", prob=0, param2=0},
		{name="air", prob=0, param2=0},
		{name="air", prob=0, param2=0},
		{name="air", prob=0, param2=0},
		{name="air", prob=0, param2=0},
		{name="air", prob=0, param2=0},
		{name="air", prob=0, param2=0},
		{name="lemontree:leaves", prob=254, param2=0},
		{name="lemontree:leaves", prob=254, param2=0},
		{name="lemontree:leaves", prob=254, param2=0},
		{name="lemontree:leaves", prob=254, param2=0},
		{name="lemontree:lemon", prob=64, param2=0},
		{name="lemontree:leaves", prob=254, param2=0},
		{name="lemontree:leaves", prob=254, param2=0},
		{name="lemontree:leaves", prob=254, param2=0},
		{name="lemontree:leaves", prob=254, param2=0},
		{name="lemontree:leaves", prob=254, param2=0},
		{name="lemontree:leaves", prob=254, param2=0},
		{name="lemontree:leaves", prob=254, param2=0},
		{name="lemontree:leaves", prob=254, param2=0},
		{name="lemontree:leaves", prob=254, param2=0},
		{name="air", prob=0, param2=0},
		{name="air", prob=0, param2=0},
		{name="air", prob=0, param2=0},
		{name="air", prob=0, param2=0},
		{name="air", prob=0, param2=0},
		{name="air", prob=0, param2=0},
		{name="air", prob=0, param2=0},
		{name="air", prob=0, param2=0},
		{name="air", prob=0, param2=0},
		{name="air", prob=0, param2=0},
		{name="air", prob=0, param2=0},
		{name="air", prob=0, param2=0},
		{name="air", prob=0, param2=0},
		{name="air", prob=0, param2=0},
		{name="air", prob=0, param2=0},
		{name="air", prob=0, param2=0},
		{name="air", prob=0, param2=0},
		{name="air", prob=0, param2=0},
		{name="air", prob=0, param2=0},
		{name="air", prob=0, param2=0},
		{name="air", prob=0, param2=0},
		{name="lemontree:leaves", prob=254, param2=0},
		{name="lemontree:trunk", prob=126, param2=20},
		{name="lemontree:lemon", prob=126, param2=0},
		{name="lemontree:trunk", prob=254, param2=9},
		{name="lemontree:leaves", prob=254, param2=0},
		{name="lemontree:leaves", prob=254, param2=0},
		{name="lemontree:leaves", prob=254, param2=0},
		{name="lemontree:leaves", prob=254, param2=0},
		{name="lemontree:leaves", prob=254, param2=0},
		{name="lemontree:leaves", prob=254, param2=0},
		{name="air", prob=0, param2=0},
		{name="lemontree:leaves", prob=254, param2=0},
		{name="lemontree:leaves", prob=254, param2=0},
		{name="lemontree:leaves", prob=254, param2=0},
		{name="lemontree:leaves", prob=254, param2=0},
		{name="air", prob=0, param2=0},
		{name="air", prob=0, param2=0},
		{name="lemontree:leaves", prob=254, param2=0},
		{name="air", prob=0, param2=0},
		{name="air", prob=0, param2=0},
		{name="air", prob=0, param2=0},
		{name="air", prob=0, param2=0},
		{name="lemontree:trunk", prob=254, param2=0, force_place=true},
		{name="air", prob=0, param2=0},
		{name="air", prob=0, param2=240},
		{name="air", prob=0, param2=0},
		{name="air", prob=0, param2=0},
		{name="lemontree:trunk", prob=254, param2=0, force_place=true},
		{name="air", prob=0, param2=0},
		{name="air", prob=0, param2=0},
		{name="air", prob=0, param2=0},
		{name="air", prob=0, param2=0},
		{name="lemontree:trunk", prob=254, param2=22, force_place=true},
		{name="air", prob=0, param2=0},
		{name="air", prob=0, param2=0},
		{name="lemontree:lemon", prob=126, param2=0},
		{name="lemontree:leaves", prob=254, param2=0},
		{name="lemontree:leaves", prob=254, param2=0},
		{name="lemontree:lemon", prob=126, param2=0},
		{name="lemontree:leaves", prob=254, param2=0},
		{name="lemontree:leaves", prob=254, param2=0},
		{name="lemontree:leaves", prob=254, param2=0},
		{name="lemontree:leaves", prob=254, param2=0},
		{name="lemontree:leaves", prob=254, param2=0},
		{name="lemontree:leaves", prob=254, param2=0},
		{name="lemontree:leaves", prob=254, param2=0},
		{name="lemontree:leaves", prob=254, param2=0},
		{name="lemontree:leaves", prob=254, param2=0},
		{name="lemontree:leaves", prob=254, param2=0},
		{name="lemontree:leaves", prob=254, param2=0},
		{name="air", prob=0, param2=0},
		{name="lemontree:leaves", prob=254, param2=0},
		{name="lemontree:leaves", prob=254, param2=0},
		{name="lemontree:leaves", prob=254, param2=0},
		{name="air", prob=0, param2=0},
		{name="air", prob=0, param2=0},
		{name="air", prob=0, param2=0},
		{name="air", prob=0, param2=0},
		{name="air", prob=0, param2=0},
		{name="air", prob=0, param2=240},
		{name="air", prob=0, param2=0},
		{name="air", prob=0, param2=0},
		{name="air", prob=0, param2=0},
		{name="air", prob=0, param2=0},
		{name="air", prob=0, param2=0},
		{name="air", prob=0, param2=0},
		{name="air", prob=0, param2=0},
		{name="air", prob=0, param2=0},
		{name="air", prob=0, param2=0},
		{name="air", prob=0, param2=0},
		{name="lemontree:leaves", prob=254, param2=0},
		{name="lemontree:trunk", prob=254, param2=9},
		{name="lemontree:lemon", prob=126, param2=0},
		{name="lemontree:trunk", prob=126, param2=23},
		{name="lemontree:leaves", prob=254, param2=0},
		{name="lemontree:leaves", prob=254, param2=0},
		{name="air", prob=0, param2=0},
		{name="lemontree:leaves", prob=254, param2=0},
		{name="lemontree:leaves", prob=254, param2=0},
		{name="lemontree:leaves", prob=254, param2=0},
		{name="lemontree:leaves", prob=254, param2=0},
		{name="lemontree:leaves", prob=254, param2=0},
		{name="lemontree:leaves", prob=254, param2=0},
		{name="lemontree:leaves", prob=254, param2=0},
		{name="lemontree:leaves", prob=254, param2=0},
		{name="air", prob=0, param2=0},
		{name="lemontree:leaves", prob=254, param2=0},
		{name="lemontree:leaves", prob=254, param2=0},
		{name="air", prob=0, param2=0},
		{name="air", prob=0, param2=0},
		{name="air", prob=0, param2=0},
		{name="air", prob=0, param2=0},
		{name="air", prob=0, param2=0},
		{name="air", prob=0, param2=0},
		{name="air", prob=0, param2=0},
		{name="air", prob=0, param2=0},
		{name="air", prob=0, param2=0},
		{name="air", prob=0, param2=0},
		{name="air", prob=0, param2=0},
		{name="air", prob=0, param2=0},
		{name="air", prob=0, param2=0},
		{name="air", prob=0, param2=0},
		{name="air", prob=0, param2=0},
		{name="air", prob=0, param2=0},
		{name="air", prob=0, param2=0},
		{name="lemontree:leaves", prob=254, param2=0},
		{name="lemontree:leaves", prob=254, param2=0},
		{name="lemontree:leaves", prob=254, param2=0},
		{name="lemontree:leaves", prob=254, param2=0},
		{name="lemontree:leaves", prob=254, param2=0},
		{name="lemontree:leaves", prob=254, param2=0},
		{name="lemontree:leaves", prob=254, param2=0},
		{name="lemontree:leaves", prob=254, param2=0},
		{name="lemontree:leaves", prob=254, param2=0},
		{name="lemontree:leaves", prob=254, param2=0},
		{name="air", prob=0, param2=0},
		{name="lemontree:leaves", prob=254, param2=0},
		{name="lemontree:leaves", prob=254, param2=0},
		{name="air", prob=0, param2=0},
		{name="air", prob=0, param2=0},
		{name="air", prob=0, param2=0},
		{name="air", prob=0, param2=0},
		{name="air", prob=0, param2=0},
		{name="air", prob=0, param2=0},
		{name="air", prob=0, param2=0},
	},
}
