schematic = {
	size = {x=9, y=12, z=10},
	yslice_prob = {
		{ypos=0, prob=254},
		{ypos=1, prob=254},
		{ypos=2, prob=254},
		{ypos=3, prob=254},
		{ypos=4, prob=254},
		{ypos=5, prob=254},
		{ypos=6, prob=254},
		{ypos=7, prob=254},
		{ypos=8, prob=254},
		{ypos=9, prob=254},
		{ypos=10, prob=254},
		{ypos=11, prob=254},
	},
	data = {
		{name="air", prob=0, param2=0},
		{name="air", prob=0, param2=0},
		{name="air", prob=0, param2=0},
		{name="air", prob=0, param2=0},
		{name="air", prob=0, param2=0},
		{name="air", prob=0, param2=0},
		{name="air", prob=0, param2=0},
		{name="air", prob=0, param2=0},
		{name="air", prob=0, param2=0},
		{name="air", prob=0, param2=0},
		{name="air", prob=0, param2=0},
		{name="air", prob=0, param2=0},
		{name="air", prob=0, param2=0},
		{name="air", prob=0, param2=0},
		{name="air", prob=0, param2=0},
		{name="air", prob=0, param2=0},
		{name="air", prob=0, param2=0},
		{name="air", prob=0, param2=0},
		{name="air", prob=0, param2=0},
		{name="air", prob=0, param2=0},
		{name="air", prob=0, param2=0},
		{name="air", prob=0, param2=0},
		{name="air", prob=0, param2=0},
		{name="air", prob=0, param2=0},
		{name="air", prob=0, param2=0},
		{name="air", prob=0, param2=0},
		{name="air", prob=0, param2=0},
		{name="air", prob=0, param2=0},
		{name="air", prob=0, param2=0},
		{name="willow:leaves", prob=254, param2=1},
		{name="air", prob=0, param2=0},
		{name="air", prob=0, param2=0},
		{name="willow:leaves", prob=254, param2=1},
		{name="air", prob=0, param2=0},
		{name="air", prob=0, param2=0},
		{name="air", prob=0, param2=0},
		{name="air", prob=0, param2=0},
		{name="air", prob=0, param2=0},
		{name="willow:leaves", prob=254, param2=1},
		{name="air", prob=0, param2=0},
		{name="air", prob=0, param2=0},
		{name="willow:leaves", prob=254, param2=1},
		{name="willow:leaves", prob=254, param2=1},
		{name="air", prob=0, param2=0},
		{name="air", prob=0, param2=0},
		{name="air", prob=0, param2=0},
		{name="air", prob=0, param2=0},
		{name="willow:leaves", prob=254, param2=1},
		{name="air", prob=0, param2=0},
		{name="air", prob=0, param2=0},
		{name="willow:leaves", prob=254, param2=1},
		{name="willow:leaves", prob=254, param2=1},
		{name="air", prob=0, param2=0},
		{name="air", prob=0, param2=0},
		{name="air", prob=0, param2=0},
		{name="air", prob=0, param2=0},
		{name="willow:leaves", prob=254, param2=1},
		{name="air", prob=0, param2=0},
		{name="air", prob=0, param2=0},
		{name="willow:leaves", prob=254, param2=1},
		{name="willow:leaves", prob=254, param2=1},
		{name="air", prob=0, param2=0},
		{name="air", prob=0, param2=0},
		{name="air", prob=0, param2=0},
		{name="air", prob=0, param2=0},
		{name="willow:leaves", prob=254, param2=1},
		{name="air", prob=0, param2=0},
		{name="willow:leaves", prob=254, param2=1},
		{name="willow:leaves", prob=254, param2=1},
		{name="willow:leaves", prob=254, param2=1},
		{name="air", prob=0, param2=0},
		{name="air", prob=0, param2=0},
		{name="air", prob=0, param2=0},
		{name="air", prob=0, param2=0},
		{name="willow:leaves", prob=254, param2=1},
		{name="willow:leaves", prob=254, param2=1},
		{name="air", prob=0, param2=0},
		{name="willow:leaves", prob=254, param2=1},
		{name="willow:leaves", prob=254, param2=1},
		{name="air", prob=0, param2=0},
		{name="air", prob=0, param2=0},
		{name="air", prob=0, param2=0},
		{name="air", prob=0, param2=0},
		{name="air", prob=0, param2=0},
		{name="air", prob=0, param2=0},
		{name="air", prob=0, param2=0},
		{name="air", prob=0, param2=0},
		{name="air", prob=0, param2=0},
		{name="air", prob=0, param2=0},
		{name="air", prob=0, param2=0},
		{name="air", prob=0, param2=0},
		{name="air", prob=0, param2=0},
		{name="air", prob=0, param2=0},
		{name="air", prob=0, param2=0},
		{name="air", prob=0, param2=0},
		{name="air", prob=0, param2=0},
		{name="air", prob=0, param2=0},
		{name="air", prob=0, param2=0},
		{name="air", prob=0, param2=0},
		{name="air", prob=0, param2=0},
		{name="air", prob=0, param2=0},
		{name="air", prob=0, param2=0},
		{name="air", prob=0, param2=0},
		{name="air", prob=0, param2=0},
		{name="air", prob=0, param2=0},
		{name="air", prob=0, param2=0},
		{name="air", prob=0, param2=0},
		{name="air", prob=0, param2=0},
		{name="air", prob=0, param2=0},
		{name="air", prob=0, param2=0},
		{name="air", prob=0, param2=0},
		{name="air", prob=0, param2=0},
		{name="air", prob=0, param2=0},
		{name="air", prob=0, param2=0},
		{name="air", prob=0, param2=0},
		{name="air", prob=0, param2=0},
		{name="air", prob=0, param2=0},
		{name="air", prob=0, param2=0},
		{name="air", prob=0, param2=0},
		{name="air", prob=0, param2=0},
		{name="air", prob=0, param2=0},
		{name="air", prob=0, param2=0},
		{name="air", prob=0, param2=0},
		{name="air", prob=0, param2=0},
		{name="air", prob=0, param2=0},
		{name="air", prob=0, param2=0},
		{name="air", prob=0, param2=0},
		{name="air", prob=0, param2=0},
		{name="air", prob=0, param2=0},
		{name="air", prob=0, param2=0},
		{name="willow:leaves", prob=254, param2=1},
		{name="air", prob=0, param2=0},
		{name="air", prob=0, param2=0},
		{name="air", prob=0, param2=0},
		{name="air", prob=0, param2=0},
		{name="air", prob=0, param2=0},
		{name="air", prob=0, param2=0},
		{name="air", prob=0, param2=0},
		{name="air", prob=0, param2=0},
		{name="willow:leaves", prob=254, param2=1},
		{name="air", prob=0, param2=0},
		{name="air", prob=0, param2=0},
		{name="air", prob=0, param2=0},
		{name="air", prob=0, param2=0},
		{name="air", prob=0, param2=0},
		{name="air", prob=0, param2=0},
		{name="air", prob=0, param2=0},
		{name="air", prob=0, param2=0},
		{name="willow:leaves", prob=254, param2=1},
		{name="air", prob=0, param2=0},
		{name="air", prob=0, param2=0},
		{name="air", prob=0, param2=0},
		{name="air", prob=0, param2=0},
		{name="air", prob=0, param2=0},
		{name="willow:leaves", prob=254, param2=1},
		{name="air", prob=0, param2=0},
		{name="willow:leaves", prob=254, param2=1},
		{name="willow:leaves", prob=254, param2=1},
		{name="air", prob=0, param2=0},
		{name="air", prob=0, param2=0},
		{name="air", prob=0, param2=0},
		{name="air", prob=0, param2=0},
		{name="air", prob=0, param2=0},
		{name="willow:leaves", prob=254, param2=1},
		{name="air", prob=0, param2=0},
		{name="willow:leaves", prob=254, param2=1},
		{name="willow:leaves", prob=254, param2=1},
		{name="willow:leaves", prob=254, param2=1},
		{name="air", prob=0, param2=0},
		{name="willow:leaves", prob=254, param2=1},
		{name="air", prob=0, param2=0},
		{name="air", prob=0, param2=0},
		{name="willow:leaves", prob=254, param2=1},
		{name="air", prob=0, param2=0},
		{name="willow:leaves", prob=254, param2=1},
		{name="willow:leaves", prob=254, param2=1},
		{name="willow:leaves", prob=254, param2=1},
		{name="air", prob=0, param2=0},
		{name="willow:leaves", prob=254, param2=1},
		{name="air", prob=0, param2=0},
		{name="air", prob=0, param2=0},
		{name="willow:leaves", prob=254, param2=1},
		{name="willow:leaves", prob=254, param2=1},
		{name="willow:leaves", prob=254, param2=1},
		{name="willow:leaves", prob=254, param2=1},
		{name="willow:leaves", prob=254, param2=1},
		{name="willow:leaves", prob=254, param2=1},
		{name="willow:leaves", prob=254, param2=1},
		{name="air", prob=0, param2=0},
		{name="air", prob=0, param2=0},
		{name="air", prob=0, param2=0},
		{name="willow:leaves", prob=254, param2=1},
		{name="willow:leaves", prob=254, param2=1},
		{name="willow:leaves", prob=254, param2=1},
		{name="willow:leaves", prob=254, param2=1},
		{name="willow:leaves", prob=254, param2=1},
		{name="air", prob=0, param2=0},
		{name="air", prob=0, param2=0},
		{name="air", prob=0, param2=0},
		{name="air", prob=0, param2=0},
		{name="air", prob=0, param2=0},
		{name="air", prob=0, param2=0},
		{name="air", prob=0, param2=0},
		{name="air", prob=0, param2=0},
		{name="air", prob=0, param2=0},
		{name="air", prob=0, param2=0},
		{name="air", prob=0, param2=0},
		{name="air", prob=0, param2=0},
		{name="air", prob=0, param2=0},
		{name="air", prob=0, param2=0},
		{name="air", prob=0, param2=0},
		{name="air", prob=0, param2=0},
		{name="air", prob=0, param2=0},
		{name="air", prob=0, param2=0},
		{name="air", prob=0, param2=0},
		{name="air", prob=0, param2=0},
		{name="air", prob=0, param2=0},
		{name="air", prob=0, param2=0},
		{name="air", prob=0, param2=0},
		{name="air", prob=0, param2=0},
		{name="air", prob=0, param2=0},
		{name="air", prob=0, param2=0},
		{name="air", prob=0, param2=0},
		{name="air", prob=0, param2=0},
		{name="air", prob=0, param2=0},
		{name="air", prob=0, param2=0},
		{name="air", prob=0, param2=0},
		{name="air", prob=0, param2=0},
		{name="air", prob=0, param2=0},
		{name="air", prob=0, param2=0},
		{name="air", prob=0, param2=0},
		{name="air", prob=0, param2=0},
		{name="air", prob=0, param2=0},
		{name="air", prob=0, param2=0},
		{name="air", prob=0, param2=0},
		{name="air", prob=0, param2=0},
		{name="air", prob=0, param2=0},
		{name="air", prob=0, param2=0},
		{name="air", prob=0, param2=0},
		{name="air", prob=0, param2=0},
		{name="air", prob=0, param2=0},
		{name="air", prob=0, param2=0},
		{name="willow:leaves", prob=254, param2=1},
		{name="air", prob=0, param2=0},
		{name="air", prob=0, param2=0},
		{name="willow:leaves", prob=254, param2=1},
		{name="air", prob=0, param2=0},
		{name="air", prob=0, param2=0},
		{name="air", prob=0, param2=0},
		{name="air", prob=0, param2=0},
		{name="air", prob=0, param2=0},
		{name="willow:leaves", prob=254, param2=1},
		{name="willow:leaves", prob=254, param2=1},
		{name="air", prob=0, param2=0},
		{name="willow:leaves", prob=254, param2=1},
		{name="air", prob=0, param2=0},
		{name="air", prob=0, param2=0},
		{name="air", prob=0, param2=0},
		{name="air", prob=0, param2=0},
		{name="air", prob=0, param2=0},
		{name="willow:leaves", prob=254, param2=1},
		{name="willow:leaves", prob=254, param2=1},
		{name="air", prob=0, param2=0},
		{name="willow:leaves", prob=254, param2=1},
		{name="air", prob=0, param2=0},
		{name="air", prob=0, param2=0},
		{name="air", prob=0, param2=0},
		{name="willow:leaves", prob=254, param2=1},
		{name="air", prob=0, param2=0},
		{name="willow:leaves", prob=254, param2=1},
		{name="willow:leaves", prob=254, param2=1},
		{name="air", prob=0, param2=0},
		{name="willow:leaves", prob=254, param2=1},
		{name="air", prob=0, param2=0},
		{name="willow:leaves", prob=254, param2=1},
		{name="air", prob=0, param2=0},
		{name="willow:leaves", prob=254, param2=1},
		{name="air", prob=0, param2=0},
		{name="willow:leaves", prob=254, param2=1},
		{name="willow:leaves", prob=254, param2=1},
		{name="willow:leaves", prob=254, param2=1},
		{name="willow:leaves", prob=254, param2=1},
		{name="willow:leaves", prob=254, param2=1},
		{name="willow:trunk", prob=254, param2=23},
		{name="willow:leaves", prob=254, param2=1},
		{name="willow:leaves", prob=254, param2=1},
		{name="air", prob=0, param2=0},
		{name="willow:leaves", prob=254, param2=1},
		{name="willow:leaves", prob=254, param2=1},
		{name="willow:leaves", prob=254, param2=1},
		{name="willow:trunk", prob=254, param2=0},
		{name="willow:trunk", prob=254, param2=0},
		{name="willow:trunk", prob=254, param2=20},
		{name="willow:trunk", prob=254, param2=20},
		{name="willow:trunk", prob=254, param2=20},
		{name="willow:leaves", prob=254, param2=1},
		{name="willow:leaves", prob=254, param2=1},
		{name="air", prob=0, param2=0},
		{name="air", prob=0, param2=0},
		{name="willow:leaves", prob=254, param2=1},
		{name="willow:leaves", prob=254, param2=1},
		{name="willow:leaves", prob=254, param2=1},
		{name="willow:leaves", prob=254, param2=1},
		{name="willow:leaves", prob=254, param2=1},
		{name="willow:leaves", prob=254, param2=1},
		{name="air", prob=0, param2=0},
		{name="air", prob=0, param2=0},
		{name="air", prob=0, param2=0},
		{name="willow:leaves", prob=254, param2=1},
		{name="willow:leaves", prob=254, param2=1},
		{name="willow:leaves", prob=254, param2=1},
		{name="willow:leaves", prob=254, param2=1},
		{name="air", prob=0, param2=0},
		{name="air", prob=0, param2=0},
		{name="air", prob=0, param2=0},
		{name="air", prob=0, param2=0},
		{name="air", prob=0, param2=0},
		{name="air", prob=0, param2=0},
		{name="air", prob=0, param2=0},
		{name="air", prob=0, param2=0},
		{name="air", prob=0, param2=0},
		{name="air", prob=0, param2=0},
		{name="air", prob=0, param2=0},
		{name="air", prob=0, param2=0},
		{name="air", prob=0, param2=0},
		{name="air", prob=0, param2=0},
		{name="air", prob=0, param2=0},
		{name="air", prob=0, param2=0},
		{name="willow:trunk", prob=254, param2=22},
		{name="air", prob=0, param2=0},
		{name="air", prob=0, param2=0},
		{name="air", prob=0, param2=0},
		{name="air", prob=0, param2=0},
		{name="air", prob=0, param2=0},
		{name="air", prob=0, param2=0},
		{name="air", prob=0, param2=0},
		{name="air", prob=0, param2=0},
		{name="willow:trunk", prob=254, param2=3},
		{name="air", prob=0, param2=0},
		{name="air", prob=0, param2=0},
		{name="air", prob=0, param2=0},
		{name="air", prob=0, param2=0},
		{name="air", prob=0, param2=0},
		{name="air", prob=0, param2=0},
		{name="air", prob=0, param2=0},
		{name="air", prob=0, param2=0},
		{name="air", prob=0, param2=0},
		{name="air", prob=0, param2=0},
		{name="air", prob=0, param2=0},
		{name="air", prob=0, param2=0},
		{name="air", prob=0, param2=0},
		{name="air", prob=0, param2=0},
		{name="air", prob=0, param2=0},
		{name="air", prob=0, param2=0},
		{name="air", prob=0, param2=0},
		{name="air", prob=0, param2=0},
		{name="willow:leaves", prob=254, param2=1},
		{name="air", prob=0, param2=0},
		{name="willow:leaves", prob=254, param2=1},
		{name="air", prob=0, param2=0},
		{name="air", prob=0, param2=0},
		{name="air", prob=0, param2=0},
		{name="air", prob=0, param2=0},
		{name="air", prob=0, param2=0},
		{name="air", prob=0, param2=0},
		{name="willow:leaves", prob=254, param2=1},
		{name="air", prob=0, param2=0},
		{name="willow:leaves", prob=254, param2=1},
		{name="air", prob=0, param2=0},
		{name="air", prob=0, param2=0},
		{name="air", prob=0, param2=0},
		{name="air", prob=0, param2=0},
		{name="air", prob=0, param2=0},
		{name="willow:leaves", prob=254, param2=1},
		{name="willow:leaves", prob=254, param2=1},
		{name="air", prob=0, param2=0},
		{name="willow:leaves", prob=254, param2=1},
		{name="air", prob=0, param2=0},
		{name="air", prob=0, param2=0},
		{name="willow:leaves", prob=254, param2=1},
		{name="air", prob=0, param2=0},
		{name="air", prob=0, param2=0},
		{name="willow:leaves", prob=254, param2=1},
		{name="willow:leaves", prob=254, param2=1},
		{name="air", prob=0, param2=0},
		{name="willow:leaves", prob=254, param2=1},
		{name="willow:leaves", prob=254, param2=1},
		{name="air", prob=0, param2=0},
		{name="willow:leaves", prob=254, param2=1},
		{name="air", prob=0, param2=0},
		{name="air", prob=0, param2=0},
		{name="willow:leaves", prob=254, param2=1},
		{name="willow:leaves", prob=254, param2=1},
		{name="willow:leaves", prob=254, param2=1},
		{name="willow:leaves", prob=254, param2=1},
		{name="willow:leaves", prob=254, param2=1},
		{name="willow:leaves", prob=254, param2=1},
		{name="willow:leaves", prob=254, param2=1},
		{name="willow:leaves", prob=254, param2=1},
		{name="willow:leaves", prob=254, param2=1},
		{name="willow:trunk", prob=254, param2=20},
		{name="willow:leaves", prob=254, param2=1},
		{name="willow:leaves", prob=254, param2=1},
		{name="willow:leaves", prob=254, param2=1},
		{name="willow:leaves", prob=254, param2=1},
		{name="air", prob=0, param2=0},
		{name="willow:leaves", prob=254, param2=1},
		{name="willow:leaves", prob=254, param2=1},
		{name="willow:leaves", prob=254, param2=1},
		{name="willow:trunk", prob=254, param2=0},
		{name="willow:leaves", prob=254, param2=1},
		{name="willow:leaves", prob=254, param2=1},
		{name="willow:leaves", prob=254, param2=1},
		{name="willow:leaves", prob=254, param2=1},
		{name="air", prob=0, param2=0},
		{name="air", prob=0, param2=0},
		{name="air", prob=0, param2=0},
		{name="willow:leaves", prob=254, param2=1},
		{name="willow:leaves", prob=254, param2=1},
		{name="willow:leaves", prob=254, param2=1},
		{name="air", prob=0, param2=0},
		{name="air", prob=0, param2=0},
		{name="air", prob=0, param2=0},
		{name="air", prob=0, param2=0},
		{name="air", prob=0, param2=0},
		{name="air", prob=0, param2=0},
		{name="willow:leaves", prob=254, param2=1},
		{name="willow:leaves", prob=254, param2=1},
		{name="air", prob=0, param2=0},
		{name="air", prob=0, param2=0},
		{name="air", prob=0, param2=0},
		{name="air", prob=0, param2=0},
		{name="air", prob=0, param2=0},
		{name="air", prob=0, param2=0},
		{name="air", prob=0, param2=0},
		{name="willow:trunk", prob=254, param2=23},
		{name="willow:trunk", prob=254, param2=23},
		{name="willow:trunk", prob=254, param2=23},
		{name="air", prob=0, param2=0},
		{name="air", prob=0, param2=0},
		{name="air", prob=0, param2=0},
		{name="air", prob=0, param2=0},
		{name="air", prob=0, param2=0},
		{name="air", prob=0, param2=0},
		{name="willow:trunk", prob=254, param2=0},
		{name="willow:trunk", prob=254, param2=20},
		{name="willow:trunk", prob=254, param2=0},
		{name="air", prob=0, param2=0},
		{name="air", prob=0, param2=0},
		{name="air", prob=0, param2=0},
		{name="air", prob=0, param2=0},
		{name="air", prob=0, param2=0},
		{name="air", prob=0, param2=0},
		{name="air", prob=0, param2=0},
		{name="willow:trunk", prob=254, param2=2},
		{name="air", prob=0, param2=0},
		{name="air", prob=0, param2=0},
		{name="air", prob=0, param2=0},
		{name="air", prob=0, param2=0},
		{name="air", prob=0, param2=0},
		{name="willow:leaves", prob=254, param2=1},
		{name="air", prob=0, param2=0},
		{name="air", prob=0, param2=0},
		{name="air", prob=0, param2=0},
		{name="air", prob=0, param2=0},
		{name="air", prob=0, param2=0},
		{name="air", prob=0, param2=0},
		{name="air", prob=0, param2=0},
		{name="air", prob=0, param2=0},
		{name="willow:leaves", prob=254, param2=1},
		{name="air", prob=0, param2=0},
		{name="willow:leaves", prob=254, param2=1},
		{name="air", prob=0, param2=0},
		{name="air", prob=0, param2=0},
		{name="air", prob=0, param2=0},
		{name="air", prob=0, param2=0},
		{name="willow:leaves", prob=254, param2=1},
		{name="air", prob=0, param2=0},
		{name="willow:leaves", prob=254, param2=1},
		{name="air", prob=0, param2=0},
		{name="willow:leaves", prob=254, param2=1},
		{name="air", prob=0, param2=0},
		{name="air", prob=0, param2=0},
		{name="air", prob=0, param2=0},
		{name="willow:leaves", prob=254, param2=1},
		{name="willow:leaves", prob=254, param2=1},
		{name="air", prob=0, param2=0},
		{name="willow:leaves", prob=254, param2=1},
		{name="air", prob=0, param2=0},
		{name="willow:leaves", prob=254, param2=1},
		{name="air", prob=0, param2=0},
		{name="air", prob=0, param2=0},
		{name="air", prob=0, param2=0},
		{name="willow:leaves", prob=254, param2=1},
		{name="willow:leaves", prob=254, param2=1},
		{name="willow:leaves", prob=254, param2=1},
		{name="willow:leaves", prob=254, param2=1},
		{name="willow:leaves", prob=254, param2=1},
		{name="willow:leaves", prob=254, param2=1},
		{name="willow:leaves", prob=254, param2=1},
		{name="air", prob=0, param2=0},
		{name="air", prob=0, param2=0},
		{name="willow:leaves", prob=254, param2=1},
		{name="willow:leaves", prob=254, param2=1},
		{name="willow:leaves", prob=254, param2=1},
		{name="willow:trunk", prob=254, param2=20},
		{name="willow:leaves", prob=254, param2=1},
		{name="willow:leaves", prob=254, param2=1},
		{name="willow:trunk", prob=254, param2=20},
		{name="willow:leaves", prob=254, param2=1},
		{name="willow:leaves", prob=254, param2=1},
		{name="willow:trunk", prob=254, param2=20},
		{name="willow:leaves", prob=254, param2=1},
		{name="willow:leaves", prob=254, param2=1},
		{name="willow:leaves", prob=254, param2=1},
		{name="willow:leaves", prob=254, param2=1},
		{name="willow:leaves", prob=254, param2=1},
		{name="willow:leaves", prob=254, param2=1},
		{name="willow:leaves", prob=254, param2=1},
		{name="willow:leaves", prob=254, param2=1},
		{name="willow:leaves", prob=254, param2=1},
		{name="willow:leaves", prob=254, param2=1},
		{name="air", prob=0, param2=0},
		{name="willow:leaves", prob=254, param2=1},
		{name="air", prob=0, param2=0},
		{name="willow:leaves", prob=254, param2=1},
		{name="willow:leaves", prob=254, param2=1},
		{name="willow:leaves", prob=254, param2=1},
		{name="air", prob=0, param2=0},
		{name="air", prob=0, param2=0},
		{name="air", prob=0, param2=0},
		{name="air", prob=0, param2=0},
		{name="air", prob=0, param2=0},
		{name="air", prob=0, param2=0},
		{name="air", prob=0, param2=0},
		{name="willow:leaves", prob=254, param2=1},
		{name="air", prob=0, param2=0},
		{name="air", prob=0, param2=0},
		{name="air", prob=0, param2=0},
		{name="air", prob=0, param2=0},
		{name="air", prob=0, param2=0},
		{name="air", prob=0, param2=0},
		{name="willow:trunk", prob=254, param2=23},
		{name="willow:trunk", prob=254, param2=23},
		{name="willow:trunk", prob=254, param2=23},
		{name="willow:trunk", prob=254, param2=23},
		{name="willow:trunk", prob=254, param2=21},
		{name="air", prob=0, param2=0},
		{name="air", prob=0, param2=0},
		{name="air", prob=0, param2=0},
		{name="air", prob=0, param2=0},
		{name="willow:trunk", prob=254, param2=2},
		{name="willow:trunk", prob=254, param2=20},
		{name="willow:trunk", prob=254, param2=3},
		{name="willow:trunk", prob=254, param2=3},
		{name="willow:trunk", prob=254, param2=3},
		{name="air", prob=0, param2=0},
		{name="air", prob=0, param2=0},
		{name="air", prob=0, param2=0},
		{name="air", prob=0, param2=0},
		{name="air", prob=0, param2=0},
		{name="willow:trunk", prob=254, param2=0},
		{name="willow:trunk", prob=254, param2=3},
		{name="willow:trunk", prob=254, param2=3},
		{name="air", prob=0, param2=0},
		{name="air", prob=0, param2=0},
		{name="air", prob=0, param2=0},
		{name="air", prob=0, param2=0},
		{name="air", prob=0, param2=0},
		{name="air", prob=0, param2=0},
		{name="air", prob=0, param2=0},
		{name="willow:trunk", prob=254, param2=3},
		{name="air", prob=0, param2=0},
		{name="air", prob=0, param2=0},
		{name="air", prob=0, param2=0},
		{name="air", prob=0, param2=0},
		{name="willow:leaves", prob=254, param2=1},
		{name="air", prob=0, param2=0},
		{name="air", prob=0, param2=0},
		{name="air", prob=0, param2=0},
		{name="willow:trunk", prob=254, param2=3},
		{name="willow:leaves", prob=254, param2=1},
		{name="air", prob=0, param2=0},
		{name="air", prob=0, param2=0},
		{name="air", prob=0, param2=0},
		{name="willow:leaves", prob=254, param2=1},
		{name="air", prob=0, param2=0},
		{name="willow:leaves", prob=254, param2=1},
		{name="air", prob=0, param2=0},
		{name="willow:trunk", prob=254, param2=3},
		{name="willow:leaves", prob=254, param2=1},
		{name="air", prob=0, param2=0},
		{name="air", prob=0, param2=0},
		{name="air", prob=0, param2=0},
		{name="willow:leaves", prob=254, param2=1},
		{name="willow:leaves", prob=254, param2=1},
		{name="willow:leaves", prob=254, param2=1},
		{name="willow:leaves", prob=254, param2=1},
		{name="willow:trunk", prob=254, param2=0},
		{name="willow:leaves", prob=254, param2=1},
		{name="air", prob=0, param2=0},
		{name="willow:leaves", prob=254, param2=1},
		{name="air", prob=0, param2=0},
		{name="willow:leaves", prob=254, param2=1},
		{name="willow:trunk", prob=254, param2=23},
		{name="willow:leaves", prob=254, param2=1},
		{name="willow:leaves", prob=254, param2=1},
		{name="willow:trunk", prob=254, param2=0},
		{name="willow:leaves", prob=254, param2=1},
		{name="willow:leaves", prob=254, param2=1},
		{name="willow:trunk", prob=254, param2=22},
		{name="willow:leaves", prob=254, param2=1},
		{name="willow:leaves", prob=254, param2=1},
		{name="willow:trunk", prob=254, param2=20},
		{name="willow:trunk", prob=254, param2=20},
		{name="willow:trunk", prob=254, param2=20},
		{name="willow:trunk", prob=254, param2=0},
		{name="willow:trunk", prob=254, param2=20},
		{name="willow:trunk", prob=254, param2=20},
		{name="willow:trunk", prob=254, param2=0},
		{name="willow:leaves", prob=254, param2=1},
		{name="willow:leaves", prob=254, param2=1},
		{name="willow:trunk", prob=254, param2=1},
		{name="willow:leaves", prob=254, param2=1},
		{name="willow:leaves", prob=254, param2=1},
		{name="willow:trunk", prob=254, param2=2},
		{name="willow:leaves", prob=254, param2=1},
		{name="willow:trunk", prob=254, param2=1},
		{name="willow:leaves", prob=254, param2=1},
		{name="air", prob=0, param2=0},
		{name="air", prob=0, param2=0},
		{name="willow:leaves", prob=254, param2=1},
		{name="willow:leaves", prob=254, param2=1},
		{name="willow:leaves", prob=254, param2=1},
		{name="willow:trunk", prob=254, param2=1},
		{name="willow:leaves", prob=254, param2=1},
		{name="willow:leaves", prob=254, param2=1},
		{name="air", prob=0, param2=0},
		{name="air", prob=0, param2=0},
		{name="air", prob=0, param2=0},
		{name="air", prob=0, param2=0},
		{name="air", prob=0, param2=0},
		{name="willow:leaves", prob=254, param2=1},
		{name="willow:leaves", prob=254, param2=1},
		{name="air", prob=0, param2=0},
		{name="air", prob=0, param2=0},
		{name="air", prob=0, param2=0},
		{name="air", prob=0, param2=0},
		{name="air", prob=0, param2=0},
		{name="air", prob=0, param2=0},
		{name="air", prob=0, param2=0},
		{name="willow:trunk", prob=254, param2=22},
		{name="willow:trunk", prob=254, param2=22},
		{name="willow:trunk", prob=254, param2=21},
		{name="air", prob=0, param2=0},
		{name="air", prob=0, param2=0},
		{name="air", prob=0, param2=0},
		{name="air", prob=0, param2=0},
		{name="air", prob=0, param2=0},
		{name="air", prob=0, param2=0},
		{name="willow:trunk", prob=254, param2=2},
		{name="willow:trunk", prob=254, param2=2},
		{name="willow:trunk", prob=254, param2=3},
		{name="air", prob=0, param2=0},
		{name="air", prob=0, param2=0},
		{name="air", prob=0, param2=0},
		{name="air", prob=0, param2=0},
		{name="air", prob=0, param2=0},
		{name="willow:leaves", prob=254, param2=1},
		{name="air", prob=0, param2=0},
		{name="willow:trunk", prob=254, param2=3},
		{name="air", prob=0, param2=0},
		{name="air", prob=0, param2=0},
		{name="air", prob=0, param2=0},
		{name="air", prob=0, param2=0},
		{name="air", prob=0, param2=0},
		{name="air", prob=0, param2=0},
		{name="willow:leaves", prob=254, param2=1},
		{name="air", prob=0, param2=0},
		{name="air", prob=0, param2=0},
		{name="air", prob=0, param2=0},
		{name="air", prob=0, param2=0},
		{name="air", prob=0, param2=0},
		{name="willow:leaves", prob=254, param2=1},
		{name="air", prob=0, param2=0},
		{name="air", prob=0, param2=0},
		{name="willow:leaves", prob=254, param2=1},
		{name="willow:leaves", prob=254, param2=1},
		{name="air", prob=0, param2=0},
		{name="air", prob=0, param2=0},
		{name="air", prob=0, param2=0},
		{name="air", prob=0, param2=0},
		{name="willow:leaves", prob=254, param2=1},
		{name="air", prob=0, param2=0},
		{name="air", prob=0, param2=0},
		{name="willow:leaves", prob=254, param2=1},
		{name="willow:leaves", prob=254, param2=1},
		{name="air", prob=0, param2=0},
		{name="air", prob=0, param2=0},
		{name="air", prob=0, param2=0},
		{name="air", prob=0, param2=0},
		{name="willow:leaves", prob=254, param2=1},
		{name="air", prob=0, param2=0},
		{name="willow:leaves", prob=254, param2=1},
		{name="willow:leaves", prob=254, param2=1},
		{name="willow:leaves", prob=254, param2=1},
		{name="willow:leaves", prob=254, param2=1},
		{name="air", prob=0, param2=0},
		{name="air", prob=0, param2=0},
		{name="air", prob=0, param2=0},
		{name="willow:leaves", prob=254, param2=1},
		{name="willow:leaves", prob=254, param2=1},
		{name="willow:leaves", prob=254, param2=1},
		{name="willow:leaves", prob=254, param2=1},
		{name="willow:leaves", prob=254, param2=1},
		{name="willow:leaves", prob=254, param2=1},
		{name="air", prob=0, param2=0},
		{name="air", prob=0, param2=0},
		{name="willow:leaves", prob=254, param2=1},
		{name="willow:leaves", prob=254, param2=1},
		{name="willow:leaves", prob=254, param2=1},
		{name="willow:trunk", prob=254, param2=20},
		{name="willow:leaves", prob=254, param2=1},
		{name="willow:leaves", prob=254, param2=1},
		{name="willow:trunk", prob=254, param2=20},
		{name="willow:leaves", prob=254, param2=1},
		{name="willow:leaves", prob=254, param2=1},
		{name="willow:trunk", prob=254, param2=20},
		{name="willow:leaves", prob=254, param2=1},
		{name="willow:leaves", prob=254, param2=1},
		{name="willow:leaves", prob=254, param2=1},
		{name="willow:leaves", prob=254, param2=1},
		{name="willow:leaves", prob=254, param2=1},
		{name="willow:leaves", prob=254, param2=1},
		{name="willow:leaves", prob=254, param2=1},
		{name="willow:leaves", prob=254, param2=1},
		{name="willow:leaves", prob=254, param2=1},
		{name="air", prob=0, param2=0},
		{name="air", prob=0, param2=0},
		{name="air", prob=0, param2=0},
		{name="air", prob=0, param2=0},
		{name="willow:leaves", prob=254, param2=1},
		{name="willow:leaves", prob=254, param2=1},
		{name="willow:leaves", prob=254, param2=1},
		{name="air", prob=0, param2=0},
		{name="air", prob=0, param2=0},
		{name="air", prob=0, param2=0},
		{name="air", prob=0, param2=0},
		{name="air", prob=0, param2=0},
		{name="air", prob=0, param2=0},
		{name="willow:leaves", prob=254, param2=1},
		{name="willow:leaves", prob=254, param2=1},
		{name="air", prob=0, param2=0},
		{name="air", prob=0, param2=0},
		{name="air", prob=0, param2=0},
		{name="air", prob=0, param2=0},
		{name="air", prob=0, param2=0},
		{name="air", prob=0, param2=0},
		{name="air", prob=0, param2=0},
		{name="air", prob=0, param2=0},
		{name="willow:trunk", prob=254, param2=23},
		{name="air", prob=0, param2=0},
		{name="air", prob=0, param2=0},
		{name="air", prob=0, param2=0},
		{name="air", prob=0, param2=0},
		{name="air", prob=0, param2=0},
		{name="air", prob=0, param2=0},
		{name="air", prob=0, param2=0},
		{name="air", prob=0, param2=0},
		{name="willow:trunk", prob=254, param2=3},
		{name="air", prob=0, param2=0},
		{name="air", prob=0, param2=0},
		{name="air", prob=0, param2=0},
		{name="air", prob=0, param2=0},
		{name="air", prob=0, param2=0},
		{name="air", prob=0, param2=0},
		{name="air", prob=0, param2=0},
		{name="air", prob=0, param2=0},
		{name="air", prob=0, param2=0},
		{name="willow:leaves", prob=254, param2=1},
		{name="air", prob=0, param2=0},
		{name="air", prob=0, param2=0},
		{name="air", prob=0, param2=0},
		{name="air", prob=0, param2=0},
		{name="air", prob=0, param2=0},
		{name="air", prob=0, param2=0},
		{name="air", prob=0, param2=0},
		{name="air", prob=0, param2=0},
		{name="willow:leaves", prob=254, param2=1},
		{name="air", prob=0, param2=0},
		{name="air", prob=0, param2=0},
		{name="air", prob=0, param2=0},
		{name="air", prob=0, param2=0},
		{name="willow:leaves", prob=254, param2=1},
		{name="air", prob=0, param2=0},
		{name="air", prob=0, param2=0},
		{name="air", prob=0, param2=0},
		{name="willow:leaves", prob=254, param2=1},
		{name="air", prob=0, param2=0},
		{name="air", prob=0, param2=0},
		{name="willow:leaves", prob=254, param2=1},
		{name="air", prob=0, param2=0},
		{name="willow:leaves", prob=254, param2=1},
		{name="air", prob=0, param2=0},
		{name="air", prob=0, param2=0},
		{name="willow:leaves", prob=254, param2=1},
		{name="willow:leaves", prob=254, param2=1},
		{name="air", prob=0, param2=0},
		{name="air", prob=0, param2=0},
		{name="willow:leaves", prob=254, param2=1},
		{name="air", prob=0, param2=0},
		{name="willow:leaves", prob=254, param2=1},
		{name="air", prob=0, param2=0},
		{name="air", prob=0, param2=0},
		{name="willow:leaves", prob=254, param2=1},
		{name="willow:leaves", prob=254, param2=1},
		{name="air", prob=0, param2=0},
		{name="air", prob=0, param2=0},
		{name="willow:leaves", prob=254, param2=1},
		{name="air", prob=0, param2=0},
		{name="willow:leaves", prob=254, param2=1},
		{name="air", prob=0, param2=0},
		{name="air", prob=0, param2=0},
		{name="willow:leaves", prob=254, param2=1},
		{name="willow:leaves", prob=254, param2=1},
		{name="air", prob=0, param2=0},
		{name="air", prob=0, param2=0},
		{name="willow:leaves", prob=254, param2=1},
		{name="willow:leaves", prob=254, param2=1},
		{name="willow:leaves", prob=254, param2=1},
		{name="air", prob=0, param2=0},
		{name="willow:leaves", prob=254, param2=1},
		{name="willow:trunk", prob=254, param2=0},
		{name="willow:leaves", prob=254, param2=1},
		{name="willow:leaves", prob=254, param2=1},
		{name="willow:leaves", prob=254, param2=1},
		{name="willow:leaves", prob=254, param2=1},
		{name="air", prob=0, param2=0},
		{name="air", prob=0, param2=0},
		{name="willow:leaves", prob=254, param2=1},
		{name="willow:leaves", prob=254, param2=1},
		{name="willow:trunk", prob=254, param2=1},
		{name="willow:leaves", prob=254, param2=1},
		{name="willow:leaves", prob=254, param2=1},
		{name="air", prob=0, param2=0},
		{name="air", prob=0, param2=0},
		{name="air", prob=0, param2=0},
		{name="air", prob=0, param2=0},
		{name="willow:leaves", prob=254, param2=1},
		{name="willow:leaves", prob=254, param2=1},
		{name="willow:leaves", prob=254, param2=1},
		{name="willow:leaves", prob=254, param2=1},
		{name="air", prob=0, param2=0},
		{name="air", prob=0, param2=0},
		{name="air", prob=0, param2=0},
		{name="air", prob=0, param2=0},
		{name="air", prob=0, param2=0},
		{name="air", prob=0, param2=0},
		{name="air", prob=0, param2=0},
		{name="willow:leaves", prob=254, param2=1},
		{name="air", prob=0, param2=0},
		{name="air", prob=0, param2=0},
		{name="air", prob=0, param2=0},
		{name="air", prob=0, param2=0},
		{name="air", prob=0, param2=0},
		{name="air", prob=0, param2=0},
		{name="air", prob=0, param2=0},
		{name="air", prob=0, param2=0},
		{name="air", prob=0, param2=0},
		{name="air", prob=0, param2=0},
		{name="air", prob=0, param2=0},
		{name="air", prob=0, param2=0},
		{name="air", prob=0, param2=0},
		{name="air", prob=0, param2=0},
		{name="air", prob=0, param2=0},
		{name="air", prob=0, param2=0},
		{name="air", prob=0, param2=0},
		{name="air", prob=0, param2=0},
		{name="air", prob=0, param2=0},
		{name="air", prob=0, param2=0},
		{name="air", prob=0, param2=0},
		{name="air", prob=0, param2=0},
		{name="air", prob=0, param2=0},
		{name="air", prob=0, param2=0},
		{name="air", prob=0, param2=0},
		{name="air", prob=0, param2=0},
		{name="air", prob=0, param2=0},
		{name="air", prob=0, param2=0},
		{name="air", prob=0, param2=0},
		{name="air", prob=0, param2=0},
		{name="air", prob=0, param2=0},
		{name="air", prob=0, param2=0},
		{name="air", prob=0, param2=0},
		{name="air", prob=0, param2=0},
		{name="air", prob=0, param2=0},
		{name="willow:leaves", prob=254, param2=1},
		{name="air", prob=0, param2=0},
		{name="air", prob=0, param2=0},
		{name="air", prob=0, param2=0},
		{name="air", prob=0, param2=0},
		{name="air", prob=0, param2=0},
		{name="air", prob=0, param2=0},
		{name="air", prob=0, param2=0},
		{name="willow:leaves", prob=254, param2=1},
		{name="willow:leaves", prob=254, param2=1},
		{name="air", prob=0, param2=0},
		{name="air", prob=0, param2=0},
		{name="air", prob=0, param2=0},
		{name="air", prob=0, param2=0},
		{name="air", prob=0, param2=0},
		{name="air", prob=0, param2=0},
		{name="air", prob=0, param2=0},
		{name="willow:leaves", prob=254, param2=1},
		{name="willow:leaves", prob=254, param2=1},
		{name="air", prob=0, param2=0},
		{name="willow:leaves", prob=254, param2=1},
		{name="air", prob=0, param2=0},
		{name="air", prob=0, param2=0},
		{name="air", prob=0, param2=0},
		{name="air", prob=0, param2=0},
		{name="air", prob=0, param2=0},
		{name="willow:leaves", prob=254, param2=1},
		{name="willow:leaves", prob=254, param2=1},
		{name="air", prob=0, param2=0},
		{name="willow:leaves", prob=254, param2=1},
		{name="willow:leaves", prob=254, param2=1},
		{name="air", prob=0, param2=0},
		{name="air", prob=0, param2=0},
		{name="willow:leaves", prob=254, param2=1},
		{name="air", prob=0, param2=0},
		{name="willow:leaves", prob=254, param2=1},
		{name="willow:trunk", prob=254, param2=21},
		{name="willow:leaves", prob=254, param2=1},
		{name="willow:leaves", prob=254, param2=1},
		{name="willow:leaves", prob=254, param2=1},
		{name="air", prob=0, param2=0},
		{name="air", prob=0, param2=0},
		{name="willow:leaves", prob=254, param2=1},
		{name="willow:leaves", prob=254, param2=1},
		{name="willow:trunk", prob=254, param2=20},
		{name="willow:trunk", prob=254, param2=20},
		{name="willow:trunk", prob=254, param2=0},
		{name="willow:leaves", prob=254, param2=1},
		{name="willow:leaves", prob=254, param2=1},
		{name="air", prob=0, param2=0},
		{name="air", prob=0, param2=0},
		{name="air", prob=0, param2=0},
		{name="air", prob=0, param2=0},
		{name="willow:leaves", prob=254, param2=1},
		{name="willow:leaves", prob=254, param2=1},
		{name="willow:leaves", prob=254, param2=1},
		{name="willow:leaves", prob=254, param2=1},
		{name="air", prob=0, param2=0},
		{name="air", prob=0, param2=0},
		{name="air", prob=0, param2=0},
		{name="air", prob=0, param2=0},
		{name="air", prob=0, param2=0},
		{name="air", prob=0, param2=0},
		{name="air", prob=0, param2=0},
		{name="air", prob=0, param2=0},
		{name="air", prob=0, param2=0},
		{name="air", prob=0, param2=0},
		{name="air", prob=0, param2=0},
		{name="air", prob=0, param2=0},
		{name="air", prob=0, param2=0},
		{name="air", prob=0, param2=0},
		{name="air", prob=0, param2=0},
		{name="air", prob=0, param2=0},
		{name="air", prob=0, param2=0},
		{name="air", prob=0, param2=0},
		{name="air", prob=0, param2=0},
		{name="air", prob=0, param2=0},
		{name="air", prob=0, param2=0},
		{name="air", prob=0, param2=0},
		{name="air", prob=0, param2=0},
		{name="air", prob=0, param2=0},
		{name="air", prob=0, param2=0},
		{name="air", prob=0, param2=0},
		{name="air", prob=0, param2=0},
		{name="air", prob=0, param2=0},
		{name="air", prob=0, param2=0},
		{name="air", prob=0, param2=0},
		{name="air", prob=0, param2=0},
		{name="air", prob=0, param2=0},
		{name="air", prob=0, param2=0},
		{name="air", prob=0, param2=0},
		{name="air", prob=0, param2=0},
		{name="air", prob=0, param2=0},
		{name="air", prob=0, param2=0},
		{name="air", prob=0, param2=0},
		{name="air", prob=0, param2=0},
		{name="air", prob=0, param2=0},
		{name="air", prob=0, param2=0},
		{name="air", prob=0, param2=0},
		{name="air", prob=0, param2=0},
		{name="air", prob=0, param2=0},
		{name="air", prob=0, param2=0},
		{name="air", prob=0, param2=0},
		{name="air", prob=0, param2=0},
		{name="air", prob=0, param2=0},
		{name="air", prob=0, param2=0},
		{name="willow:leaves", prob=254, param2=1},
		{name="air", prob=0, param2=0},
		{name="air", prob=0, param2=0},
		{name="air", prob=0, param2=0},
		{name="air", prob=0, param2=0},
		{name="air", prob=0, param2=0},
		{name="air", prob=0, param2=0},
		{name="air", prob=0, param2=0},
		{name="air", prob=0, param2=0},
		{name="willow:leaves", prob=254, param2=1},
		{name="air", prob=0, param2=0},
		{name="air", prob=0, param2=0},
		{name="air", prob=0, param2=0},
		{name="air", prob=0, param2=0},
		{name="willow:leaves", prob=254, param2=1},
		{name="air", prob=0, param2=0},
		{name="air", prob=0, param2=0},
		{name="air", prob=0, param2=0},
		{name="willow:leaves", prob=254, param2=1},
		{name="air", prob=0, param2=0},
		{name="air", prob=0, param2=0},
		{name="air", prob=0, param2=0},
		{name="air", prob=0, param2=0},
		{name="willow:leaves", prob=254, param2=1},
		{name="air", prob=0, param2=0},
		{name="air", prob=0, param2=0},
		{name="air", prob=0, param2=0},
		{name="willow:leaves", prob=254, param2=1},
		{name="air", prob=0, param2=0},
		{name="air", prob=0, param2=0},
		{name="air", prob=0, param2=0},
		{name="air", prob=0, param2=0},
		{name="willow:leaves", prob=254, param2=1},
		{name="air", prob=0, param2=0},
		{name="air", prob=0, param2=0},
		{name="air", prob=0, param2=0},
		{name="willow:leaves", prob=254, param2=1},
		{name="willow:leaves", prob=254, param2=1},
		{name="willow:leaves", prob=254, param2=1},
		{name="willow:leaves", prob=254, param2=1},
		{name="air", prob=0, param2=0},
		{name="willow:leaves", prob=254, param2=1},
		{name="air", prob=0, param2=0},
		{name="air", prob=0, param2=0},
		{name="air", prob=0, param2=0},
		{name="willow:leaves", prob=254, param2=1},
		{name="willow:leaves", prob=254, param2=1},
		{name="willow:leaves", prob=254, param2=1},
		{name="willow:leaves", prob=254, param2=1},
		{name="air", prob=0, param2=0},
		{name="air", prob=0, param2=0},
		{name="air", prob=0, param2=0},
		{name="air", prob=0, param2=0},
		{name="air", prob=0, param2=0},
		{name="air", prob=0, param2=0},
		{name="air", prob=0, param2=0},
		{name="air", prob=0, param2=0},
		{name="air", prob=0, param2=0},
		{name="air", prob=0, param2=0},
		{name="air", prob=0, param2=0},
		{name="air", prob=0, param2=0},
		{name="air", prob=0, param2=0},
		{name="air", prob=0, param2=0},
		{name="air", prob=0, param2=0},
		{name="air", prob=0, param2=0},
		{name="air", prob=0, param2=0},
		{name="air", prob=0, param2=0},
		{name="air", prob=0, param2=0},
		{name="air", prob=0, param2=0},
		{name="air", prob=0, param2=0},
		{name="air", prob=0, param2=0},
		{name="air", prob=0, param2=0},
		{name="air", prob=0, param2=0},
		{name="air", prob=0, param2=0},
		{name="air", prob=0, param2=0},
		{name="air", prob=0, param2=0},
		{name="air", prob=0, param2=0},
		{name="air", prob=0, param2=0},
		{name="air", prob=0, param2=0},
	},
}
